2023-05-05 22:25:15,990 INFO    MainThread:3695 [wandb_setup.py:_flush():68] Configure stats pid to 3695
2023-05-05 22:25:15,990 INFO    MainThread:3695 [wandb_setup.py:_flush():68] Loading settings from /home/yx/.config/wandb/settings
2023-05-05 22:25:15,991 INFO    MainThread:3695 [wandb_setup.py:_flush():68] Loading settings from /mnt/c/kust/kust/python_code/python_code/code/experiments/unet/wandb/settings
2023-05-05 22:25:15,991 INFO    MainThread:3695 [wandb_setup.py:_flush():68] Loading settings from environment variables: {'_require_service': 'True'}
2023-05-05 22:25:15,991 INFO    MainThread:3695 [wandb_setup.py:_flush():68] Inferring run settings from compute environment: {'program_relpath': 'myunet.py', 'program': '/mnt/c/kust/kust/python_code/python_code/code/experiments/unet/myunet.py'}
2023-05-05 22:25:15,991 INFO    MainThread:3695 [wandb_init.py:_log_setup():476] Logging user logs to ./runs/wandb/run-20230505_222515-2duyij4y/logs/debug.log
2023-05-05 22:25:15,992 INFO    MainThread:3695 [wandb_init.py:_log_setup():477] Logging internal logs to ./runs/wandb/run-20230505_222515-2duyij4y/logs/debug-internal.log
2023-05-05 22:25:15,992 INFO    MainThread:3695 [wandb_init.py:init():516] calling init triggers
2023-05-05 22:25:15,992 INFO    MainThread:3695 [wandb_init.py:init():519] wandb.init called with sweep_config: {}
config: {}
2023-05-05 22:25:15,992 INFO    MainThread:3695 [wandb_init.py:init():569] starting backend
2023-05-05 22:25:15,992 INFO    MainThread:3695 [wandb_init.py:init():573] setting up manager
2023-05-05 22:25:15,994 INFO    MainThread:3695 [backend.py:_multiprocessing_setup():102] multiprocessing start_methods=fork,spawn,forkserver, using: spawn
2023-05-05 22:25:15,997 INFO    MainThread:3695 [wandb_init.py:init():580] backend started and connected
2023-05-05 22:25:15,999 INFO    MainThread:3695 [wandb_init.py:init():658] updated telemetry
2023-05-05 22:25:16,007 INFO    MainThread:3695 [wandb_init.py:init():693] communicating run to backend with 60 second timeout
2023-05-05 22:26:16,070 ERROR   MainThread:3695 [wandb_init.py:init():704] backend process timed out
2023-05-05 22:26:16,071 ERROR   MainThread:3695 [wandb_init.py:init():713] encountered error: Error communicating with wandb process
For more info see: https://docs.wandb.ai/library/init#init-start-error
2023-05-05 22:26:22,893 ERROR   Thread-40 :3695 [retry.py:__call__():154] Retry attempt failed:
Traceback (most recent call last):
  File "/home/yx/miniconda3/envs/mat/lib/python3.9/site-packages/urllib3/connectionpool.py", line 449, in _make_request
    six.raise_from(e, None)
  File "<string>", line 3, in raise_from
  File "/home/yx/miniconda3/envs/mat/lib/python3.9/site-packages/urllib3/connectionpool.py", line 444, in _make_request
    httplib_response = conn.getresponse()
  File "/home/yx/miniconda3/envs/mat/lib/python3.9/http/client.py", line 1377, in getresponse
    response.begin()
  File "/home/yx/miniconda3/envs/mat/lib/python3.9/http/client.py", line 320, in begin
    version, status, reason = self._read_status()
  File "/home/yx/miniconda3/envs/mat/lib/python3.9/http/client.py", line 281, in _read_status
    line = str(self.fp.readline(_MAXLINE + 1), "iso-8859-1")
  File "/home/yx/miniconda3/envs/mat/lib/python3.9/socket.py", line 704, in readinto
    return self._sock.recv_into(b)
  File "/home/yx/miniconda3/envs/mat/lib/python3.9/ssl.py", line 1242, in recv_into
    return self.read(nbytes, buffer)
  File "/home/yx/miniconda3/envs/mat/lib/python3.9/ssl.py", line 1100, in read
    return self._sslobj.read(len, buffer)
socket.timeout: The read operation timed out

During handling of the above exception, another exception occurred:

Traceback (most recent call last):
  File "/home/yx/miniconda3/envs/mat/lib/python3.9/site-packages/requests/adapters.py", line 439, in send
    resp = conn.urlopen(
  File "/home/yx/miniconda3/envs/mat/lib/python3.9/site-packages/urllib3/connectionpool.py", line 787, in urlopen
    retries = retries.increment(
  File "/home/yx/miniconda3/envs/mat/lib/python3.9/site-packages/urllib3/util/retry.py", line 550, in increment
    raise six.reraise(type(error), error, _stacktrace)
  File "/home/yx/miniconda3/envs/mat/lib/python3.9/site-packages/urllib3/packages/six.py", line 770, in reraise
    raise value
  File "/home/yx/miniconda3/envs/mat/lib/python3.9/site-packages/urllib3/connectionpool.py", line 703, in urlopen
    httplib_response = self._make_request(
  File "/home/yx/miniconda3/envs/mat/lib/python3.9/site-packages/urllib3/connectionpool.py", line 451, in _make_request
    self._raise_timeout(err=e, url=url, timeout_value=read_timeout)
  File "/home/yx/miniconda3/envs/mat/lib/python3.9/site-packages/urllib3/connectionpool.py", line 340, in _raise_timeout
    raise ReadTimeoutError(
urllib3.exceptions.ReadTimeoutError: HTTPSConnectionPool(host='api.wandb.ai', port=443): Read timed out. (read timeout=10)

During handling of the above exception, another exception occurred:

Traceback (most recent call last):
  File "/home/yx/miniconda3/envs/mat/lib/python3.9/site-packages/wandb/sdk/lib/retry.py", line 113, in __call__
    result = self._call_fn(*args, **kwargs)
  File "/home/yx/miniconda3/envs/mat/lib/python3.9/site-packages/wandb/sdk/internal/internal_api.py", line 210, in execute
    return self.client.execute(*args, **kwargs)  # type: ignore
  File "/home/yx/miniconda3/envs/mat/lib/python3.9/site-packages/wandb/vendor/gql-0.2.0/wandb_gql/client.py", line 52, in execute
    result = self._get_result(document, *args, **kwargs)
  File "/home/yx/miniconda3/envs/mat/lib/python3.9/site-packages/wandb/vendor/gql-0.2.0/wandb_gql/client.py", line 60, in _get_result
    return self.transport.execute(document, *args, **kwargs)
  File "/home/yx/miniconda3/envs/mat/lib/python3.9/site-packages/wandb/vendor/gql-0.2.0/wandb_gql/transport/requests.py", line 38, in execute
    request = requests.post(self.url, **post_args)
  File "/home/yx/miniconda3/envs/mat/lib/python3.9/site-packages/requests/api.py", line 119, in post
    return request('post', url, data=data, json=json, **kwargs)
  File "/home/yx/miniconda3/envs/mat/lib/python3.9/site-packages/requests/api.py", line 61, in request
    return session.request(method=method, url=url, **kwargs)
  File "/home/yx/miniconda3/envs/mat/lib/python3.9/site-packages/requests/sessions.py", line 542, in request
    resp = self.send(prep, **send_kwargs)
  File "/home/yx/miniconda3/envs/mat/lib/python3.9/site-packages/requests/sessions.py", line 655, in send
    r = adapter.send(request, **kwargs)
  File "/home/yx/miniconda3/envs/mat/lib/python3.9/site-packages/requests/adapters.py", line 529, in send
    raise ReadTimeout(e, request=request)
requests.exceptions.ReadTimeout: HTTPSConnectionPool(host='api.wandb.ai', port=443): Read timed out. (read timeout=10)
2023-05-05 22:27:23,813 WARNING MsgRouterThr:3695 [router.py:message_loop():77] message_loop has been closed
